<?xml version="1.0" encoding="utf-8"?><testsuite errors="0" failures="1" name="" skips="0" tests="1" time="24.942"><testcase classname="scripts.LoginTest.CheckLoginExample" name="test_login_show_gear" time="22.349656105"><failure message="test failure">Traceback (most recent call last):
  File &quot;/Users/apailthorp/pysaunter_spike/conftest.py&quot;, line 32, in pytest_runtest_call
    raise(e)
KeyError: &apos;gear&apos;</failure></testcase></testsuite>